 * Serving Flask app 'app'
 * Debug mode: on
WARNING: This is a development server. Do not use it in a production deployment. Use a production WSGI server instead.
 * Running on http://127.0.0.1:5000
Press CTRL+C to quit
 * Restarting with stat
 * Debugger is active!
 * Debugger PIN: 181-994-900
127.0.0.1 - - [14/Feb/2025 16:09:44] "POST /register HTTP/1.1" 500 -
Traceback (most recent call last):
  File "C:\Users\Lenovo\AppData\Local\Programs\Python\Python312\Lib\site-packages\sqlalchemy\engine\base.py", line 1964, in _exec_single_context
    self.dialect.do_execute(
  File "C:\Users\Lenovo\AppData\Local\Programs\Python\Python312\Lib\site-packages\sqlalchemy\engine\default.py", line 942, in do_execute
    cursor.execute(statement, parameters)
psycopg2.errors.UniqueViolation: duplicate key value violates unique constraint "user_email_key"
DETAIL:  Key (email)=(john@example.com) already exists.


The above exception was the direct cause of the following exception:

Traceback (most recent call last):
  File "C:\Users\Lenovo\AppData\Local\Programs\Python\Python312\Lib\site-packages\flask\app.py", line 1536, in __call__
    return self.wsgi_app(environ, start_response)
           ^^^^^^^^^^^^^^^^^^^^^^^^^^^^^^^^^^^^^^
  File "C:\Users\Lenovo\AppData\Local\Programs\Python\Python312\Lib\site-packages\flask\app.py", line 1514, in wsgi_app
    response = self.handle_exception(e)
               ^^^^^^^^^^^^^^^^^^^^^^^^
  File "C:\Users\Lenovo\AppData\Local\Programs\Python\Python312\Lib\site-packages\flask_cors\extension.py", line 194, in wrapped_function
    return cors_after_request(app.make_response(f(*args, **kwargs)))
                                                ^^^^^^^^^^^^^^^^^^^^
  File "C:\Users\Lenovo\AppData\Local\Programs\Python\Python312\Lib\site-packages\flask\app.py", line 1511, in wsgi_app
    response = self.full_dispatch_request()
               ^^^^^^^^^^^^^^^^^^^^^^^^^^^^
  File "C:\Users\Lenovo\AppData\Local\Programs\Python\Python312\Lib\site-packages\flask\app.py", line 919, in full_dispatch_request
    rv = self.handle_user_exception(e)
         ^^^^^^^^^^^^^^^^^^^^^^^^^^^^^
  File "C:\Users\Lenovo\AppData\Local\Programs\Python\Python312\Lib\site-packages\flask_cors\extension.py", line 194, in wrapped_function
    return cors_after_request(app.make_response(f(*args, **kwargs)))
                                                ^^^^^^^^^^^^^^^^^^^^
  File "C:\Users\Lenovo\AppData\Local\Programs\Python\Python312\Lib\site-packages\flask\app.py", line 917, in full_dispatch_request
    rv = self.dispatch_request()
         ^^^^^^^^^^^^^^^^^^^^^^^
  File "C:\Users\Lenovo\AppData\Local\Programs\Python\Python312\Lib\site-packages\flask\app.py", line 902, in dispatch_request
    return self.ensure_sync(self.view_functions[rule.endpoint])(**view_args)  # type: ignore[no-any-return]
           ^^^^^^^^^^^^^^^^^^^^^^^^^^^^^^^^^^^^^^^^^^^^^^^^^^^^^^^^^^^^^^^^^^^^^^^^^^^^^^^^^^^^^^^^^^^^^^^^
  File "C:\Users\Lenovo\Desktop\Accomodation and mess search\Backend\routes.py", line 12, in register
    db.session.commit()
  File "C:\Users\Lenovo\AppData\Local\Programs\Python\Python312\Lib\site-packages\sqlalchemy\orm\scoping.py", line 599, in commit
    return self._proxied.commit()
           ^^^^^^^^^^^^^^^^^^^^^^
  File "C:\Users\Lenovo\AppData\Local\Programs\Python\Python312\Lib\site-packages\sqlalchemy\orm\session.py", line 2032, in commit
    trans.commit(_to_root=True)
  File "<string>", line 2, in commit
  File "C:\Users\Lenovo\AppData\Local\Programs\Python\Python312\Lib\site-packages\sqlalchemy\orm\state_changes.py", line 139, in _go
    ret_value = fn(self, *arg, **kw)
                ^^^^^^^^^^^^^^^^^^^^
  File "C:\Users\Lenovo\AppData\Local\Programs\Python\Python312\Lib\site-packages\sqlalchemy\orm\session.py", line 1313, in commit
    self._prepare_impl()
  File "<string>", line 2, in _prepare_impl
  File "C:\Users\Lenovo\AppData\Local\Programs\Python\Python312\Lib\site-packages\sqlalchemy\orm\state_changes.py", line 139, in _go
    ret_value = fn(self, *arg, **kw)
                ^^^^^^^^^^^^^^^^^^^^
  File "C:\Users\Lenovo\AppData\Local\Programs\Python\Python312\Lib\site-packages\sqlalchemy\orm\session.py", line 1288, in _prepare_impl
    self.session.flush()
  File "C:\Users\Lenovo\AppData\Local\Programs\Python\Python312\Lib\site-packages\sqlalchemy\orm\session.py", line 4353, in flush
    self._flush(objects)
  File "C:\Users\Lenovo\AppData\Local\Programs\Python\Python312\Lib\site-packages\sqlalchemy\orm\session.py", line 4488, in _flush
    with util.safe_reraise():
         ^^^^^^^^^^^^^^^^^^^^
  File "C:\Users\Lenovo\AppData\Local\Programs\Python\Python312\Lib\site-packages\sqlalchemy\util\langhelpers.py", line 146, in __exit__
    raise exc_value.with_traceback(exc_tb)
  File "C:\Users\Lenovo\AppData\Local\Programs\Python\Python312\Lib\site-packages\sqlalchemy\orm\session.py", line 4449, in _flush
    flush_context.execute()
  File "C:\Users\Lenovo\AppData\Local\Programs\Python\Python312\Lib\site-packages\sqlalchemy\orm\unitofwork.py", line 466, in execute
    rec.execute(self)
  File "C:\Users\Lenovo\AppData\Local\Programs\Python\Python312\Lib\site-packages\sqlalchemy\orm\unitofwork.py", line 642, in execute
    util.preloaded.orm_persistence.save_obj(
  File "C:\Users\Lenovo\AppData\Local\Programs\Python\Python312\Lib\site-packages\sqlalchemy\orm\persistence.py", line 93, in save_obj
    _emit_insert_statements(
  File "C:\Users\Lenovo\AppData\Local\Programs\Python\Python312\Lib\site-packages\sqlalchemy\orm\persistence.py", line 1233, in _emit_insert_statements
    result = connection.execute(
             ^^^^^^^^^^^^^^^^^^^
  File "C:\Users\Lenovo\AppData\Local\Programs\Python\Python312\Lib\site-packages\sqlalchemy\engine\base.py", line 1416, in execute
    return meth(
           ^^^^^
  File "C:\Users\Lenovo\AppData\Local\Programs\Python\Python312\Lib\site-packages\sqlalchemy\sql\elements.py", line 516, in _execute_on_connection
    return connection._execute_clauseelement(
           ^^^^^^^^^^^^^^^^^^^^^^^^^^^^^^^^^^
  File "C:\Users\Lenovo\AppData\Local\Programs\Python\Python312\Lib\site-packages\sqlalchemy\engine\base.py", line 1638, in _execute_clauseelement
    ret = self._execute_context(
          ^^^^^^^^^^^^^^^^^^^^^^
  File "C:\Users\Lenovo\AppData\Local\Programs\Python\Python312\Lib\site-packages\sqlalchemy\engine\base.py", line 1843, in _execute_context
    return self._exec_single_context(
           ^^^^^^^^^^^^^^^^^^^^^^^^^^
  File "C:\Users\Lenovo\AppData\Local\Programs\Python\Python312\Lib\site-packages\sqlalchemy\engine\base.py", line 1983, in _exec_single_context
    self._handle_dbapi_exception(
  File "C:\Users\Lenovo\AppData\Local\Programs\Python\Python312\Lib\site-packages\sqlalchemy\engine\base.py", line 2352, in _handle_dbapi_exception
    raise sqlalchemy_exception.with_traceback(exc_info[2]) from e
  File "C:\Users\Lenovo\AppData\Local\Programs\Python\Python312\Lib\site-packages\sqlalchemy\engine\base.py", line 1964, in _exec_single_context
    self.dialect.do_execute(
  File "C:\Users\Lenovo\AppData\Local\Programs\Python\Python312\Lib\site-packages\sqlalchemy\engine\default.py", line 942, in do_execute
    cursor.execute(statement, parameters)
sqlalchemy.exc.IntegrityError: (psycopg2.errors.UniqueViolation) duplicate key value violates unique constraint "user_email_key"
DETAIL:  Key (email)=(john@example.com) already exists.

[SQL: INSERT INTO "user" (name, email, password) VALUES (%(name)s, %(email)s, %(password)s) RETURNING "user".id]
[parameters: {'name': 'John', 'email': 'john@example.com', 'password': 'scrypt:32768:8:1$lokMmBO7GqnH3C6H$3456265bccb73d92ade356e08a331867d3c907b1f0f1252e291d0842b7e154589f33cfc8ccf276ec85418ef4687b7d4b8862cd57f02265f2044b8f42a77bdecf'}]
(Background on this error at: https://sqlalche.me/e/20/gkpj)
